Workbook
Name profilversion: "2.0.0"

Sheet Info
A1: Information
A2: Samtliga SKALL och BÖR krav som finns definierade i REST API profilen på Diggs Utvecklarportal finns sammanställd i fliken Kravlista REST API profil. Detta dokument avser underlätta avstämning av ett enskilt API gentemot profilen. Förutom kraven så finns kravets respektive område länkat till profilen, dess typning och status samt möjlighet att lägga kommentar per krav. Förklaring av status: - = Krav ej bedömt OK = Krav bedömt och hanterat för att möta kravet Pågående = Krav bedömt och hantering påbörjat men ej klart NOK = Krav bedömt men API möter inte kravet N/A = Krav bedömt men inte applicerbart på API | O2: Värden i nedan tabeller ska inte förändras! Data hämtas från fliken Kravlista REST API profil. Det är också där avstämning sker gentemot ert API, dvs där värde för Status anges per krav.
A3: ="Kraven avser version "&profilversion&" av REST API profilen som i juni 2026 publicerades på https://dev.dataportal.se/rest-api-profil" -> Kraven avser version 2.0.0 av REST API profilen som i juni 2026 publicerades på https://dev.dataportal.se/rest-api-profil
A4: Avstämning av krav
A5: Fördelning per status för alla krav
A6: - | B6: OK | C6: Pågående | D6: NOK | E6: N/A
A7: =COUNTIF('Kravlista REST API profil'!E2:E195,"-") -> 156 | B7: =COUNTIF('Kravlista REST API profil'!E2:E195,"OK") -> 0 | C7: =COUNTIF('Kravlista REST API profil'!E2:E195,"Pågående") -> 0 | D7: =COUNTIF('Kravlista REST API profil'!E2:E195,"NOK") -> 0 | E7: =COUNTIF('Kravlista REST API profil'!E2:E195,"N/A") -> 0 | F7: antal
A8: =(A7/SUM(A7:E7)) -> 1 | B8: =(B7/SUM(A7:E7)) -> 0 | C8: =(C7/SUM(A7:E7)) -> 0 | D8: =(D7/SUM(A7:E7)) -> 0 | E8: =(E7/SUM(A7:E7)) -> 0 | F8: andel
A10: Fördelning per område
A11: =('Kravlista REST API profil'!$A2) -> Dokumentation | H11: =('Kravlista REST API profil'!$A27) -> Datum- och tidsformat
A12: =$A$6 -> - | B12: =$B$6 -> OK | C12: =$C$6 -> Pågående | D12: =$D$6 -> NOK | E12: =$E$6 -> N/A | H12: =$A$6 -> - | I12: =$B$6 -> OK | J12: =$C$6 -> Pågående | K12: =$D$6 -> NOK | L12: =$E$6 -> N/A
A13: =COUNTIF('Kravlista REST API profil'!E2:E26,"-") -> 23 | B13: =COUNTIF('Kravlista REST API profil'!E2:E26,"OK") -> 0 | C13: =COUNTIF('Kravlista REST API profil'!E2:E26,"Pågående") -> 0 | D13: =COUNTIF('Kravlista REST API profil'!E2:E26,"NOK") -> 0 | E13: =COUNTIF('Kravlista REST API profil'!E2:E26,"N/A") -> 0 | F13: antal | H13: =COUNTIF('Kravlista REST API profil'!E27:E32,"-") -> 4 | I13: =COUNTIF('Kravlista REST API profil'!E27:E32,"OK") -> 0 | J13: =COUNTIF('Kravlista REST API profil'!E27:E32,"Pågående") -> 0 | K13: =COUNTIF('Kravlista REST API profil'!E27:E32,"NOK") -> 0 | L13: =COUNTIF('Kravlista REST API profil'!E27:E32,"N/A") -> 0 | M13: antal
A14: =(A13/SUM(A13:E13)) -> 1 | B14: =(B13/SUM(A13:E13)) -> 0 | C14: =(C13/SUM(A13:E13)) -> 0 | D14: =(D13/SUM(A13:E13)) -> 0 | E14: =(E13/SUM(A13:E13)) -> 0 | F14: andel | H14: =(H13/SUM(H13:L13)) -> 1 | I14: =(I13/SUM(H13:L13)) -> 0 | J14: =(J13/SUM(H13:L13)) -> 0 | K14: =(K13/SUM(H13:L13)) -> 0 | L14: =(L13/SUM(H13:L13)) -> 0 | M14: andel
A16: =('Kravlista REST API profil'!$A33) -> Resurser | H16: =('Kravlista REST API profil'!$A40) -> URL format och namngivning
A17: =$A$6 -> - | B17: =$B$6 -> OK | C17: =$C$6 -> Pågående | D17: =$D$6 -> NOK | E17: =$E$6 -> N/A | H17: =$A$6 -> - | I17: =$B$6 -> OK | J17: =$C$6 -> Pågående | K17: =$D$6 -> NOK | L17: =$E$6 -> N/A
A18: =COUNTIF('Kravlista REST API profil'!E33:E39,"-") -> 5 | B18: =COUNTIF('Kravlista REST API profil'!E33:E39,"OK") -> 0 | C18: =COUNTIF('Kravlista REST API profil'!E33:E39,"Pågående") -> 0 | D18: =COUNTIF('Kravlista REST API profil'!E33:E39,"NOK") -> 0 | E18: =COUNTIF('Kravlista REST API profil'!E33:E39,"N/A") -> 0 | F18: antal | H18: =COUNTIF('Kravlista REST API profil'!E40:E50,"-") -> 8 | I18: =COUNTIF('Kravlista REST API profil'!E40:E50,"OK") -> 0 | J18: =COUNTIF('Kravlista REST API profil'!E40:E50,"Pågående") -> 0 | K18: =COUNTIF('Kravlista REST API profil'!E40:E50,"NOK") -> 0 | L18: =COUNTIF('Kravlista REST API profil'!E40:E50,"N/A") -> 0 | M18: antal
A19: =(A18/SUM(A18:E18)) -> 1 | B19: =(B18/SUM(A18:E18)) -> 0 | C19: =(C18/SUM(A18:E18)) -> 0 | D19: =(D18/SUM(A18:E18)) -> 0 | E19: =(E18/SUM(A18:E18)) -> 0 | F19: andel | H19: =(H18/SUM(H18:L18)) -> 1 | I19: =(I18/SUM(H18:L18)) -> 0 | J19: =(J18/SUM(H18:L18)) -> 0 | K19: =(K18/SUM(H18:L18)) -> 0 | L19: =(L18/SUM(H18:L18)) -> 0 | M19: andel
A21: =('Kravlista REST API profil'!$A51) -> Mognad | H21: =('Kravlista REST API profil'!$A54) -> Säkerhet
A22: =$A$6 -> - | B22: =$B$6 -> OK | C22: =$C$6 -> Pågående | D22: =$D$6 -> NOK | E22: =$E$6 -> N/A | H22: =$A$6 -> - | I22: =$B$6 -> OK | J22: =$C$6 -> Pågående | K22: =$D$6 -> NOK | L22: =$E$6 -> N/A
A23: =COUNTIF('Kravlista REST API profil'!E51:E53,"-") -> 3 | B23: =COUNTIF('Kravlista REST API profil'!E51:E53,"OK") -> 0 | C23: =COUNTIF('Kravlista REST API profil'!E51:E53,"Pågående") -> 0 | D23: =COUNTIF('Kravlista REST API profil'!E51:E53,"NOK") -> 0 | E23: =COUNTIF('Kravlista REST API profil'!E51:E53,"N/A") -> 0 | F23: antal | H23: =COUNTIF('Kravlista REST API profil'!E54:E95,"-") -> 33 | I23: =COUNTIF('Kravlista REST API profil'!E54:E95,"OK") -> 0 | J23: =COUNTIF('Kravlista REST API profil'!E54:E95,"Pågående") -> 0 | K23: =COUNTIF('Kravlista REST API profil'!E54:E95,"NOK") -> 0 | L23: =COUNTIF('Kravlista REST API profil'!E54:E95,"N/A") -> 0 | M23: antal
A24: =(A23/SUM(A23:E23)) -> 1 | B24: =(B23/SUM(A23:E23)) -> 0 | C24: =(C23/SUM(A23:E23)) -> 0 | D24: =(D23/SUM(A23:E23)) -> 0 | E24: =(E23/SUM(A23:E23)) -> 0 | F24: andel | H24: =(H23/SUM(H23:L23)) -> 1 | I24: =(I23/SUM(H23:L23)) -> 0 | J24: =(J23/SUM(H23:L23)) -> 0 | K24: =(K23/SUM(H23:L23)) -> 0 | L24: =(L23/SUM(H23:L23)) -> 0 | M24: andel
A26: =('Kravlista REST API profil'!$A96) -> API Message | H26: =('Kravlista REST API profil'!$A104) -> API Request
A27: =$A$6 -> - | B27: =$B$6 -> OK | C27: =$C$6 -> Pågående | D27: =$D$6 -> NOK | E27: =$E$6 -> N/A | H27: =$A$6 -> - | I27: =$B$6 -> OK | J27: =$C$6 -> Pågående | K27: =$D$6 -> NOK | L27: =$E$6 -> N/A
A28: =COUNTIF('Kravlista REST API profil'!E96:E103,"-") -> 6 | B28: =COUNTIF('Kravlista REST API profil'!E96:E103,"OK") -> 0 | C28: =COUNTIF('Kravlista REST API profil'!E96:E103,"Pågående") -> 0 | D28: =COUNTIF('Kravlista REST API profil'!E96:E103,"NOK") -> 0 | E28: =COUNTIF('Kravlista REST API profil'!E96:E103,"N/A") -> 0 | F28: antal | H28: =COUNTIF('Kravlista REST API profil'!E104:E110,"-") -> 5 | I28: =COUNTIF('Kravlista REST API profil'!E104:E110,"OK") -> 0 | J28: =COUNTIF('Kravlista REST API profil'!E104:E110,"Pågående") -> 0 | K28: =COUNTIF('Kravlista REST API profil'!E104:E110,"NOK") -> 0 | L28: =COUNTIF('Kravlista REST API profil'!E104:E110,"N/A") -> 0 | M28: antal
A29: =(A28/SUM(A28:E28)) -> 1 | B29: =(B28/SUM(A28:E28)) -> 0 | C29: =(C28/SUM(A28:E28)) -> 0 | D29: =(D28/SUM(A28:E28)) -> 0 | E29: =(E28/SUM(A28:E28)) -> 0 | F29: andel | H29: =(H28/SUM(H28:L28)) -> 1 | I29: =(I28/SUM(H28:L28)) -> 0 | J29: =(J28/SUM(H28:L28)) -> 0 | K29: =(K28/SUM(H28:L28)) -> 0 | L29: =(L28/SUM(H28:L28)) -> 0 | M29: andel
A31: =('Kravlista REST API profil'!$A111) -> API Response | H31: =('Kravlista REST API profil'!$A115) -> Felhantering
A32: =$A$6 -> - | B32: =$B$6 -> OK | C32: =$C$6 -> Pågående | D32: =$D$6 -> NOK | E32: =$E$6 -> N/A | H32: =$A$6 -> - | I32: =$B$6 -> OK | J32: =$C$6 -> Pågående | K32: =$D$6 -> NOK | L32: =$E$6 -> N/A
A33: =COUNTIF('Kravlista REST API profil'!E111:E114,"-") -> 3 | B33: =COUNTIF('Kravlista REST API profil'!E111:E114,"OK") -> 0 | C33: =COUNTIF('Kravlista REST API profil'!E111:E114,"Pågående") -> 0 | D33: =COUNTIF('Kravlista REST API profil'!E111:E114,"NOK") -> 0 | E33: =COUNTIF('Kravlista REST API profil'!E111:E114,"N/A") -> 0 | F33: antal | H33: =COUNTIF('Kravlista REST API profil'!E115:E116,"-") -> 2 | I33: =COUNTIF('Kravlista REST API profil'!E115:E116,"OK") -> 0 | J33: =COUNTIF('Kravlista REST API profil'!E115:E116,"Pågående") -> 0 | K33: =COUNTIF('Kravlista REST API profil'!E115:E116,"NOK") -> 0 | L33: =COUNTIF('Kravlista REST API profil'!E115:E116,"N/A") -> 0 | M33: antal
A34: =(A33/SUM(A33:E33)) -> 1 | B34: =(B33/SUM(A33:E33)) -> 0 | C34: =(C33/SUM(A33:E33)) -> 0 | D34: =(D33/SUM(A33:E33)) -> 0 | E34: =(E33/SUM(A33:E33)) -> 0 | F34: andel | H34: =(H33/SUM(H33:L33)) -> 1 | I34: =(I33/SUM(H33:L33)) -> 0 | J34: =(J33/SUM(H33:L33)) -> 0 | K34: =(K33/SUM(H33:L33)) -> 0 | L34: =(L33/SUM(H33:L33)) -> 0 | M34: andel
A36: =('Kravlista REST API profil'!$A117) -> Versionshantering | H36: =('Kravlista REST API profil'!$A142) -> Spårbarhet och korrelation
A37: =$A$6 -> - | B37: =$B$6 -> OK | C37: =$C$6 -> Pågående | D37: =$D$6 -> NOK | E37: =$E$6 -> N/A | H37: =$A$6 -> - | I37: =$B$6 -> OK | J37: =$C$6 -> Pågående | K37: =$D$6 -> NOK | L37: =$E$6 -> N/A
A38: =COUNTIF('Kravlista REST API profil'!E117:E141,"-") -> 19 | B38: =COUNTIF('Kravlista REST API profil'!E117:E141,"OK") -> 0 | C38: =COUNTIF('Kravlista REST API profil'!E117:E141,"Pågående") -> 0 | D38: =COUNTIF('Kravlista REST API profil'!E117:E141,"NOK") -> 0 | E38: =COUNTIF('Kravlista REST API profil'!E117:E141,"N/A") -> 0 | F38: antal | H38: =COUNTIF('Kravlista REST API profil'!E142:E147,"-") -> 6 | I38: =COUNTIF('Kravlista REST API profil'!E142:E147,"OK") -> 0 | J38: =COUNTIF('Kravlista REST API profil'!E142:E147,"Pågående") -> 0 | K38: =COUNTIF('Kravlista REST API profil'!E142:E147,"NOK") -> 0 | L38: =COUNTIF('Kravlista REST API profil'!E142:E147,"N/A") -> 0 | M38: antal
A39: =(A38/SUM(A38:E38)) -> 1 | B39: =(B38/SUM(A38:E38)) -> 0 | C39: =(C38/SUM(A38:E38)) -> 0 | D39: =(D38/SUM(A38:E38)) -> 0 | E39: =(E38/SUM(A38:E38)) -> 0 | F39: andel | H39: =(H38/SUM(H38:L38)) -> 1 | I39: =(I38/SUM(H38:L38)) -> 0 | J39: =(J38/SUM(H38:L38)) -> 0 | K39: =(K38/SUM(H38:L38)) -> 0 | L39: =(L38/SUM(H38:L38)) -> 0 | M39: andel
A41: =('Kravlista REST API profil'!$A148) -> Webhooks | H41: =('Kravlista REST API profil'!$A154) -> Hypermedia
A42: =$A$6 -> - | B42: =$B$6 -> OK | C42: =$C$6 -> Pågående | D42: =$D$6 -> NOK | E42: =$E$6 -> N/A | H42: =$A$6 -> - | I42: =$B$6 -> OK | J42: =$C$6 -> Pågående | K42: =$D$6 -> NOK | L42: =$E$6 -> N/A
A43: =COUNTIF('Kravlista REST API profil'!E148:E153,"-") -> 6 | B43: =COUNTIF('Kravlista REST API profil'!E148:E153,"OK") -> 0 | C43: =COUNTIF('Kravlista REST API profil'!E148:E153,"Pågående") -> 0 | D43: =COUNTIF('Kravlista REST API profil'!E148:E153,"NOK") -> 0 | E43: =COUNTIF('Kravlista REST API profil'!E148:E153,"N/A") -> 0 | F43: antal | H43: =COUNTIF('Kravlista REST API profil'!E154:E178,"-") -> 19 | I43: =COUNTIF('Kravlista REST API profil'!E154:E178,"OK") -> 0 | J43: =COUNTIF('Kravlista REST API profil'!E154:E178,"Pågående") -> 0 | K43: =COUNTIF('Kravlista REST API profil'!E154:E178,"NOK") -> 0 | L43: =COUNTIF('Kravlista REST API profil'!E154:E178,"N/A") -> 0 | M43: antal
A44: =(A43/SUM(A43:E43)) -> 1 | B44: =(B43/SUM(A43:E43)) -> 0 | C44: =(C43/SUM(A43:E43)) -> 0 | D44: =(D43/SUM(A43:E43)) -> 0 | E44: =(E43/SUM(A43:E43)) -> 0 | F44: andel | H44: =(H43/SUM(H43:L43)) -> 1 | I44: =(I43/SUM(H43:L43)) -> 0 | J44: =(J43/SUM(H43:L43)) -> 0 | K44: =(K43/SUM(H43:L43)) -> 0 | L44: =(L43/SUM(H43:L43)) -> 0 | M44: andel
A46: =('Kravlista REST API profil'!$A179) -> Filtrering, namnsättning och sökparametrar | H46: =('Kravlista REST API profil'!$A195) -> Cachning
A47: =$A$6 -> - | B47: =$B$6 -> OK | C47: =$C$6 -> Pågående | D47: =$D$6 -> NOK | E47: =$E$6 -> N/A | H47: =$A$6 -> - | I47: =$B$6 -> OK | J47: =$C$6 -> Pågående | K47: =$D$6 -> NOK | L47: =$E$6 -> N/A
A48: =COUNTIF('Kravlista REST API profil'!E179:E194,"-") -> 13 | B48: =COUNTIF('Kravlista REST API profil'!E179:E194,"OK") -> 0 | C48: =COUNTIF('Kravlista REST API profil'!E179:E194,"Pågående") -> 0 | D48: =COUNTIF('Kravlista REST API profil'!E179:E194,"NOK") -> 0 | E48: =COUNTIF('Kravlista REST API profil'!E179:E194,"N/A") -> 0 | F48: antal | H48: =COUNTIF('Kravlista REST API profil'!E195,"-") -> 1 | I48: =COUNTIF('Kravlista REST API profil'!E195,"OK") -> 0 | J48: =COUNTIF('Kravlista REST API profil'!E195,"Pågående") -> 0 | K48: =COUNTIF('Kravlista REST API profil'!E195,"NOK") -> 0 | L48: =COUNTIF('Kravlista REST API profil'!E195,"N/A") -> 0 | M48: antal
...

Sheet Kravlista REST API profil
A1: Område | B1: ID | C1: Krav | D1: Typ | E1: Status | F1: Kommentar
A2: Dokumentation | B2: DOK.01 | C2: I regel BÖR dokumentationen och specifikationen för ett API finnas allmänt tillgänglig online. | D2: BÖR | E2: -
B3: DOK.02 | C3: Vidare BÖR ett API:s dokumentation och specifikation finnas sökbara via Sveriges dataportal. | D3: BÖR | E3: -
B4: API dokumentation
B5: DOK.03 | C5: Dokumentationen för ett API SKALL innehålla följande: • Om API • Användarvillkor • Datamodell för representation av resurser • Krav på autentisering • Livscykelhantering och versionshantering • Kontaktuppgifter | D5: SKALL | E5: -
B6: DOK.04 | C6: Dokumentationen och i synnerhet specifikationen SKALL ses som ett kontrakt mellan designer och utvecklare samt mellan producent och konsument av API:et. | D6: SKALL | E6: -
B7: DOK.05 | C7: Dokumentationen SKALL versionshanteras tillsammans med API:et. | D7: SKALL | E7: -
B8: DOK.06 | C8: Dokumentationen BÖR finnas på både svenska och engelska. | D8: BÖR | E8: -
B9: DOK.07 | C9: Dokumentationen av ett API BÖR innehålla övergripande information om API:et. | D9: BÖR | E9: -
B10: DOK.08 | C10: Ett API:s servicenivå SKALL finnas tydligt beskrivna i dokumentationen. | D10: SKALL | E10: -
B11: DOK.09 | C11: Kända problem och begränsningar SKALL finnas tydlig beskrivning dokumentationen. | D11: SKALL | E11: -
B12: DOK.10 | C12: Om det är känt SKALL tidpunkt för när API:et tas ur bruk anges i dokumentationen. | D12: SKALL | E12: -
B13: DOK.11 | C13: Avsikten och beteendet hos API:et SKALL beskrivas så utförligt och tydligt som möjligt. | D13: SKALL | E13: -
B14: DOK.12 | C14: Ett API:s resurser och de möjliga operationer som kan utföras på resursen SKALL beskrivas så utförligt och tydligt som möjligt. | D14: SKALL | E14: -
B15: DOK.13 | C15: Förväntade returkoder och felkoder SKALL vara fullständigt dokumenterade. | D15: SKALL | E15: -
B16: DOK.15 | C16: I dokumentationen av API:et SKALL exempel på API:ets fråga (en:request) och svar (en:reply) finnas i sin helhet. | D16: SKALL | E16: -
B17: API specifikation
B18: DOK.16 | C18: REST API:er SKALL ha en API specifikation som bör kunna generera en datamodell för representation av API:ets resurser. | D18: SKALL | E18: -
B19: DOK.17 | C19: API specifikation BÖR dokumenteras med den senaste major-versionen av OpenAPI Specification. | D19: BÖR | E19: -
B20: DOK.18 | C20: API specifikationen BÖR beskrivas med antingen JSON eller YAML. | D20: BÖR | E20: -
B21: DOK.19 | C21: Ett API:s resurser och de möjliga operationer som kan utföras på resursen SKALL beskrivas så utförligt och tydligt som möjligt. | D21: SKALL | E21: -
B22: DOK.20 | C22: Förväntade returkoder och felkoder SKALL vara fullständigt dokumenterade. | D22: SKALL | E22: -
B23: DOK.21 | C23: Krav på autentisering SKALL anges i specifikationen. | D23: SKALL | E23: -
B24: DOK.22 | C24: Varje ny major-version av ett API, enligt versionshanteringsavsnittet, SKALL följas av en ny API specifikation. | D24: SKALL | E24: -
B25: DOK.23 | C25: API specifikationen SKALL återfinnas under API-roten, det vill säga: {protokoll}://{domännamn}/{API}/{version}/ | D25: SKALL | E25: -
B26: DOK.24 | C26: Om API specifikationen specificeras med OpenAPI SKALL roten till specifikationen namnges med openapi.yaml eller openapi.json. | D26: SKALL | E26: -
A27: Datum- och tidsformat | B27: DOT.01 | C27: Datum och tid SKALL hanteras enligt följande: • Använd alltid RFC 3339 för datum och tid • Acceptera alla tidszoner i API:er • Returnera datum och tid i UTC • Använd inte tidsdelen om du inte behöver den | D27: SKALL | E27: -
B28: Datum och tid
B29: DOT.02 | C29: Datum och tid SKALL anges enligt RFC 3339 som bygger på ISO-8601. | D29: SKALL | E29: -
B30: Tidszoner
B31: DOT.03 | C31: När man använder RFC 3339 format BÖR tidszonen anges. | D31: BÖR | E31: -
B32: DOT.04 | C32: Tidzonen BÖR representeras med UTC formatet, där tid anges som offset från UTC (Coordinated Universal Time). | D32: BÖR | E32: -
A33: Resurser | B33: Identifierare
B34: RES.02 | C34: Primärnycklar eller personligt identifierbar information (personnummer, etc) BÖR INTE exponeras. | D34: BÖR INTE | E34: -
B35: RES.03 | C35: När numeriska ID:n används BÖR de INTE vara sekventiella. Om informationen är av känslig karaktär ska den skyddas med behörighetskontroll. | D35: BÖR INTE | E35: -
B36: RES.04 | C36: En identifierare för en nästlad resurs SKALL vara unik inom sin förälder resurs om den är beroende av sin förälder. | D36: SKALL | E36: -
B37: RES.05 | C37: När det kommer till att identifiera resurser så BÖR designen av detta ta höjd för en del olika aspekter: • Säkerhet – beakta den identifikation på resurs som förmedlas via API gällande om den kan anses vara känslig eller onödig att exponera. T.ex. består en identifierare av en räknare så är det enkelt att lista ut nästa resurs. Avstå också från att använda primärnycklar i databasen utåt. • Användandet av logiska nycklar – den logiska nyckeln används i exponering utåt medan relationer döljs i backend. Passar bra när resurserna tillhör en domän, såsom SEK tillhör domänen valutor. • Överväg användande av UUID (eller motsvarande) – likt de två ovanstående punkterna så används databasgenererade id:n för att hantera data i backend, medan den logiska nyckeln döljs genom att skapa en UUID (t.ex. genom MD5 hashning av logisk nyckel). UUID kan såklart också genereras trots att det inte finns en logisk nyckel att använda. | D37: BÖR | E37: -
B38: Namnsättningskonvention för resurser
B39: RES.06 | C39: Följande regler för resurser SKALL följas: • Resurser namnges som substantiv. • Resurser namnges i pluralform, även om den nu kända träffbilden bara ger ett resultat • Resurser följer den namnsättningskonvention som beskrivs för URL:er, det vill säga att resurser anges med gemener, använder endast alfanumeriska tecken och bindestreck för att separera eventuella ord. | D39: SKALL | E39: -
A40: URL format och namngivning | B40: URL komponenter
...
